Workbook

Sheet Calculation for sizing HDT 
B2: PROJECT : | D2: SALMAN PLATFORM
B3: DATE: | D3: 43869
B4: Revision: | D4: 0
B6: Minimum inlet pressure | D6: 16 | E6: barg
B7: Inlet air temperature | D7: 20 | E7: °C
B8: Nominal Flow "Q" | D8: 7000 | E8: Nm3/hr | G8: -20 | H8: 10 min.
B9: Corrosion Allowance C.A. | D9: 1.5 | E9: - | G9: -40 | H9: 7 min.
B10: Required presserized Dew Point | D10: -20 | E10: °C | G10: -60 | H10: 5 Min.
B11: Internal Painting | D11: SA 2.1/2 100 micron Epoxy
B12: External Painting | D12: SA 2.1/2 40 micron Zinc Rich Epoxy Primer 40 micron High Build Epoxy Polyamide 40 micron Aliphatic Polyurethane Top Coat Total: 120 micron
B15: Correction Factor
B16: Inlet Pressure (Barg) | E16: 4 | F16: 5 | G16: 6 | H16: 7 | I16: 8 | J16: 9 | K16: 10 | L16: 11 | M16: 12 | N16: 13 | O16: 14 | P16: 15 | Q16: 16
B17: Correction Factor | E17: 0.62 | F17: 0.77 | G17: 0.9 | H17: 1 | I17: 1.09 | J17: 1.17 | K17: 1.24 | L17: 1.31 | M17: 1.37 | N17: 1.42 | O17: 1.47 | P17: 1.52 | Q17: 1.56
B19: Correction Factor | N19: Model | O19: Inlet Air Flow-Rate
B20: Inlet Air Temperature (°C) | E20: <25 | F20: 30 | G20: 35 | H20: 40 | I20: 45 | J20: 50 | K20: 55 | L20: 60 | O20: NI/min | P20: Nm3/h | Q20: scfm
B21: Correction Factor | E21: 1.12 | F21: 1.06 | G21: 1 | H21: 0.93 | I21: 0.86 | J21: 0.78 | K21: 0.7 | L21: 0.6 | N21: HDT-3 | O21: 320 | P21: =0.06*O21 -> 19.2 | Q21: =O21*0.03531467 -> 11.300694
N22: HDT-5 | O22: 530 | P22: =0.06*O22 -> 31.8 | Q22: =O22*0.03531467 -> 18.716775
B23: Interpolation | E23: Interpolation | N23: HDT-8 | O23: 760 | P23: =0.06*O23 -> 45.6 | Q23: =O23*0.03531467 -> 26.839149
B24: Pressure | C24: Corr. Factor | E24: Temperature | F24: Corr. Factor | N24: HDT-12 | O24: 1200 | P24: =0.06*O24 -> 72 | Q24: =O24*0.03531467 -> 42.377604
B25: =ROUNDDOWN(B26,0) -> 16 | C25: =IF(B25=E16,E17,IF(B25=F16,F17,IF(B25=G16,G17,IF(B25=H16,H17,IF(B25=I16,I17,IF(B25=J16,J17,IF(B25=K16,K17,IF(B25=L16,L17,IF(B25=M16,M17,IF(B25=N16,N17,IF(B25=O16,O17,IF(B25=P16,P17,IF(B25=Q16,Q17))))))))))))) -> 1.56 | E25: =IF($E$26<=25,25,IF($E$26<30,25,IF($E$26<35,30,IF($E$26<40,35,IF($E$26<45,40,IF($E$26<50,45,IF($E$26<55,50,IF($E$26<60,55)))))))) -> 25 | F25: =IF($E$25=25,$E$21,IF($E$25=$F$20,$F$21,IF($E$25=$G$20,$G$21,IF($E$25=H20,H21,IF($E$25=$I$20,$I$21,IF($E$25=$J$20,$J$21,IF($E$25=$K$20,$K$21,IF($E$25=$L$20,$L$21)))))))) -> 1.12 | N25: HDT-18 | O25: 1850 | P25: =0.06*O25 -> 111 | Q25: =O25*0.03531467 -> 65.332139
B26: =$D$6 -> 16 | C26: =IF(B26=E16,E17,IF(B26=F16,F17,IF(B26=G16,G17,IF(B26=H16,H17,IF(B26=I16,I17,IF(B26=J16,J17,IF(B26=K16,K17,IF(B26=L16,L17,IF(B26=M16,M17,IF(B26=N16,N17,IF(B26=O16,O17,IF(B26=P16,P17,IF(B26=Q16,Q17,(((B26-B25)*(C27-C25))/(B27-B25))+C25))))))))))))) -> 1.56 | E26: =$D$7 -> 20 | F26: =IF($E$26=$F$20,$F$21,IF($E$26=$G$20,$G$21,IF($E$26=$H$20,$H$21,IF($E$26=$H$20,$H$21,IF($E$26=$I$20,$I$21,IF($E$26=$J$20,$J$21,IF($E$26=$K$20,$K$21,IF($E$26=$L$20,$L$21,((($E$26-$E$25)*($F$27-$F$25))/($E$27-$E$25))+$F$25)))))))) -> 1.18 | N26: HDT-25 | O26: 2500 | P26: =0.06*O26 -> 150 | Q26: =O26*0.03531467 -> 88.286675
B27: =ROUNDUP(B26,0) -> 16 | C27: =IF(B27=E16,E17,IF(B27=F16,F17,IF(B27=G16,G17,IF(B27=H16,H17,IF(B27=I16,I17,IF(B27=J16,J17,IF(B27=K16,K17,IF(B27=L16,L17,IF(B27=M16,M17,IF(B27=N16,N17,IF(B27=O16,O17,IF(B27=P16,P17,IF(B27=Q16,Q17))))))))))))) -> 1.56 | E27: =$E$25+5 -> 30 | F27: =IF($E$27=25,$E$21,IF($E$27=$F$20,$F$21,IF($E$27=$G$20,$G$21,IF($E$27=$H$20,$H$21,IF($E$27=$I$20,$I$21,IF($E$27=$J$20,$J$21,IF($E$27=$K$20,$K$21,IF($E$27=$L$20,$L$21)))))))) -> 1.06 | N27: HDT-30 | O27: 3000 | P27: =0.06*O27 -> 180 | Q27: =O27*0.03531467 -> 105.94401
N28: HDT-40 | O28: 3900 | P28: =0.06*O28 -> 234 | Q28: =O28*0.03531467 -> 137.72721
E29: Actuator Weight (kg) | N29: HDT-50 | O29: 5000 | P29: =0.06*O29 -> 300 | Q29: =O29*0.03531467 -> 176.57335
C30: size | D30: weight (kg) | H30: Butterfly valve (Flange Connection) | I30: size | J30: weight (kg) | N30: HDT-60 | O30: 6200 | P30: =0.06*O30 -> 372 | Q30: =O30*0.03531467 -> 218.95095
B31: Ball Valve With Actuator 1/2" | C31: 1/2" | D31: 5 | E31: 1.2 | F31: =D31+E31 -> 6.2 | I31: 2" | J31: 4 | N31: HDT-75 | O31: 7500 | P31: =0.06*O31 -> 450 | Q31: =O31*0.03531467 -> 264.86003
B32: Ball Valve With Actuator 3/4" | C32: 3/4" | D32: 7 | E32: 1.3 | F32: =D32+E32 -> 8.3 | I32: 2.1/2" | J32: 4.5 | N32: HDT-90 | O32: 9000 | P32: =0.06*O32 -> 540 | Q32: =O32*0.03531467 -> 317.83203
B33: Ball Valve With Actuator 1" | C33: 1" | D33: 10 | E33: 2.1 | F33: =D33+E33 -> 12.1 | I33: 3" | J33: 5 | N33: HDT-130 | O33: 12800 | P33: =0.06*O33 -> 768 | Q33: =O33*0.03531467 -> 452.02778
B34: Ball Valve With Actuator 11/2" | C34: 11/2" | D34: 15 | E34: 4.2 | F34: =D34+E34 -> 19.2 | I34: 4" | J34: 9 | N34: HDT-160 | O34: 16200 | P34: =0.06*O34 -> 972 | Q34: =O34*0.03531467 -> 572.09765
I35: 5" | J35: 14 | N35: HDT-200 | O35: 20500 | P35: =0.06*O35 -> 1230 | Q35: =O35*0.03531467 -> 723.95074
B36: Butterfly valve (Flange Connection) | C36: size | D36: weight (kg) | I36: 6" | J36: 14 | N36: HDT-250 | O36: 25500 | P36: =0.06*O36 -> 1530 | Q36: =O36*0.03531467 -> 900.52409
C37: 1/2" | D37: 5 | I37: 8" | J37: 22 | N37: HDT-300 | O37: 30000 | P37: =0.06*O37 -> 1800 | Q37: =O37*0.03531467 -> 1059.4401
C38: 3/4" | D38: 7 | N38: HDT-350 | O38: 36000 | P38: =0.06*O38 -> 2160 | Q38: =O38*0.03531467 -> 1271.3281
C39: 1" | D39: 10 | N39: HDT-400 | O39: 42000 | P39: =0.06*O39 -> 2520 | Q39: =O39*0.03531467 -> 1483.2161
C40: 1.1/2" | D40: 18 | N40: HDT-450 | O40: 45600 | P40: =0.06*O40 -> 2736 | Q40: =O40*0.03531467 -> 1610.349
C41: 2" | D41: 19 | N41: HDT-620 | O41: 62500 | P41: =0.06*O41 -> 3750 | Q41: =O41*0.03531467 -> 2207.1669
C42: 2.1/2" | D42: 26 | N42: HDT-800 | O42: 81000 | P42: =0.06*O42 -> 4860 | Q42: =O42*0.03531467 -> 2860.4883
C43: 3" | D43: 29 | N43: HDT-1000 | O43: 102000 | P43: =0.06*O43 -> 6120 | Q43: =O43*0.03531467 -> 3602.0963
C44: 4" | D44: 48 | N44: HDT-1200 | O44: 126000 | P44: =0.06*O44 -> 7560 | Q44: =O44*0.03531467 -> 4449.6484
C45: 5" | D45: 69 | N45: HDT-1500 | O45: 151000 | P45: =0.06*O45 -> 9060 | Q45: =O45*0.03531467 -> 5332.5152
...

Sheet Vessel Weights
B2: VESSEL WEIGHTS
C6: Input data
C7: Output data
B9: CYLINDRICAL SHELL
B11: P | C11: Design pressure | F11: P = | G11: =I11*14.5038 -> 261.0684 | H11: psi | I11: =ROUNDDOWN('Calculation for sizing HDT '!D6+2,0) -> 18 | J11: barg | M11: Allowable Stress * | Q11: Density
B12: S* | C12: allowable stress | F12: S = | G12: =I12*145.038 -> 20000.74 | H12: psi | I12: =P12 -> 137.9 | J12: N/mm2 | M12: SA-516Gr.70 | O12: S= | P12: 137.9 | Q12: N/mm2 | R12: ρ = | S12: 7750 | T12: Kg/m3
B13: E | C13: Joint efficiency | F13: E = | G13: =I13 -> 0.85 | H13: — | I13: 0.85 | J13: — | M13: SA-36 | O13: S= | P13: 114.5 | Q13: N/mm2 | R13: ρ = | S13: 7750 | T13: Kg/m3
B14: R | C14: Inside raduis | F14: R = | G14: =I14/25.4 -> 17.716535 | H14: in | I14: =I15/2 -> 450 | J14: mm | M14: SA-283C | O14: S= | P14: 108.3 | Q14: N/mm2 | R14: ρ = | S14: 7750 | T14: Kg/m3
B15: ID | C15: Inside dia. | F15: OD = | G15: =I15/25.4 -> 35.433071 | H15: in | I15: ='Calculation for sizing HDT '!D93 -> 900 | J15: mm | M15: SA-240 316L | O15: S= | P15: 115.1 | Q15: N/mm2 | R15: ρ = | S15: 8027 | T15: Kg/m3
B16: t | C16: wall thk. | F16: C.A. = | G16: =I16/25.4 -> 0.059055118 | H16: in | I16: ='Calculation for sizing HDT '!D9 -> 1.5 | J16: mm | M16: SA-240 304L | O16: S= | P16: 115.1 | Q16: N/mm2 | R16: ρ = | S16: 8027 | T16: Kg/m3
B17: WL. To WL. | C17: Length | F17: L = | G17: =I17/25.4 -> 59.055118 | H17: in | I17: ='Calculation for sizing HDT '!E93 -> 1500 | J17: mm | M17: SA-240 316 | O17: S= | P17: 137.9 | Q17: N/mm2 | R17: ρ = | S17: 8027 | T17: Kg/m3
B18: C.A. | C18: Corrosion Allowance | F18: t = | G18: =((G11*G14)/(G12*G13+(0.4*G11)))+G16 -> 0.3294563 | H18: in | I18: =G18*25.4 -> 8.3681901 | J18: mm | M18: SA-240 304 | O18: S= | P18: 137.9 | Q18: N/mm2 | R18: ρ = | S18: 8027 | T18: Kg/m3
B19: t = P * R/(SE + 0.4P) | M19: SA-240 31803 | O19: S= | P19: 177.2 | Q19: N/mm2 | R19: ρ = | S19: 8027 | T19: Kg/m3
B21: Shell Thickness | D21: =IF(ROUNDUP(I18,0)=4,4,IF(ROUNDUP(I18,0)=5,5,IF(ROUNDUP(I18,0)=6,6,IF(ROUNDUP(I18,0)=7,8,IF(ROUNDUP(I18,0)=8,8,IF(ROUNDUP(I18,0)=9,10,IF(ROUNDUP(I18,0)=10,10,IF(ROUNDUP(I18,0)=11,12,IF(ROUNDUP(I18,0)=12,12,IF(ROUNDUP(I18,0)=13,14,IF(ROUNDUP(I18,0)=14,14,IF(ROUNDUP(I18,0)=15,15,IF(ROUNDUP(I18,0)=16,16,IF(ROUNDUP(I18,0)=17,18,IF(ROUNDUP(I18,0)=18,18,IF(ROUNDUP(I18,0)=19,20,IF(ROUNDUP(I18,0)=20,20,IF(ROUNDUP(I18,0)=21,22,IF(ROUNDUP(I18,0)=23,24,IF(ROUNDUP(I18,0)=24,24,IF(ROUNDUP(I18,0)=25,25))))))))))))))))))))) -> 10 | E21: mm
B23: Following formula has been used for calculating the Cylindrical weight:
B24: Cylindrical weight = π x ID x thk x ρ x L
B25: where, | I25: S.F. = | K25: 50 | L25: mm
B26: π = 3.141 | I26: π = | K26: 3.141 | L26: —
B27: ID = Inside Diameter | I27: ID = | K27: =$I$15-2*D21 -> 880 | L27: mm
B28: thk = Thickness of Shell | I28: thk. = | K28: =$D$21 -> 10 | L28: mm
B29: ρ = Density of Material | I29: ρ = | K29: =$S$12 -> 7750 | L29: Kg/m3
B30: L = Shell Length | I30: L = | K30: =$I$17 -> 1500 | L30: mm | N30: Cylindrical weight=
I31: Cylindrical weight= | K31: =K26*(K27/1000)*(K28/1000)*(K30/1000)*K29 -> 321.3243 | L31: mm | N31: Cylindrical weight= | P31: =K31*1.1 -> 353.45673 | Q31: Kg
B32: NOTE:
B33: In the PV Elite software multiplies the total weight of the vessel by 1.0 plus.
B35: 2:1 ELLIPSOIDAL HEAD
B37: P | C37: Design pressure | F37: P = | G37: =I37*14.5038 -> 261.0684 | H37: psi | I37: =$I$11 -> 18 | J37: barg | N37: S.F. = | P37: 50 | Q37: mm
B38: S* | C38: allowable stress | F38: S = | G38: =I38*145.038 -> 20000.74 | H38: psi | I38: =$I$12 -> 137.9 | J38: N/mm2 | N38: π = | P38: 3.141 | Q38: —
B39: E | C39: Joint efficiency | F39: E = | G39: =$I$39 -> 1 | H39: — | I39: 1 | J39: — | N39: ID = | P39: =I41-2*D46 -> 880 | Q39: mm
B40: R | C40: Outside raduis | F40: R = | G40: =I40/25.4 -> 17.716535 | H40: in | I40: =$I$41/2 -> 450 | J40: mm | N40: thk. = | P40: =D46 -> 10 | Q40: mm
B41: D | C41: Outside dia. | F41: OD = | G41: =I41/25.4 -> 35.433071 | H41: in | I41: =$I$15 -> 900 | J41: mm | N41: ρ = | P41: =$S$12 -> 7750 | Q41: Kg/m3
B42: t | C42: wall thk. | F42: C.A. = | G42: =I42/25.4 -> 0.059055118 | H42: in | I42: =$I$16 -> 1.5 | J42: mm | N42: L = | P42: =P37 -> 50 | Q42: mm
B43: C.A. | C43: Corrosion Allowance | F43: t = | G43: =((G37*G41)/(2*G38*G39+1.8*G37))+G42 -> 0.28762281 | H43: in | I43: =G43*25.4 -> 7.3056193 | J43: mm | N43: Cylindrical weight= | P43: =P38*(P39/1000)*(P40/1000)*(P42/1000)*P41 -> 10.71081 | Q43: mm
B44: t = P * D/(2SE + 1.8P)
O45: ts/L<0.002 | Q45: As per Appendix 1-4 ASME VIII div.1
B46: Head Thickness | D46: =IF(ROUNDUP(I43,0)=4,6,IF(ROUNDUP(I43,0)=5,6,IF(ROUNDUP(I43,0)=6,8,IF(ROUNDUP(I43,0)=7,8,IF(ROUNDUP(I43,0)=8,10,IF(ROUNDUP(I43,0)=9,12,IF(ROUNDUP(I43,0)=10,12,IF(ROUNDUP(I43,0)=11,14,IF(ROUNDUP(I43,0)=12,14,IF(ROUNDUP(I43,0)=13,15,IF(ROUNDUP(I43,0)=14,16,IF(ROUNDUP(I43,0)=15,18,IF(ROUNDUP(I43,0)=16,18,IF(ROUNDUP(I43,0)=17,20,IF(ROUNDUP(I43,0)=18,20,IF(ROUNDUP(I43,0)=19,22,IF(ROUNDUP(I43,0)=20,22,IF(ROUNDUP(I43,0)=21,24,IF(ROUNDUP(I43,0)=23,26,IF(ROUNDUP(I43,0)=24,26,IF(ROUNDUP(I43,0)=25,28))))))))))))))))))))) -> 10 | E46: mm | O46: ts<= | P46: (250*D/500)/251
O47: ts<= | P47: =(250*I41/500)/251 -> 1.7928287 | Q47: mm | S47: ID= | T47: =I41-(2*P47)+I42 -> 897.91434
B48: Following formula has been used for calculating the Ellipsoidal head blank weight: | S48: Kcor= | T48: =(2+(T47/(T47/2))^2)/6 -> 1
B49: Blank Weight = (π * BD² * thk * ρ )/ 4 | O49: tr=PDoKcor/2SE+2P(Kcor-0.1)
B50: where, | J50: S.F. = | K50: 50 | L50: mm | O50: tr= | P50: =((G37*G41*T48)/(2*G38*G39+2*G37*(T48-0.1)))+G42 -> 0.28762281 | R50: tr= | S50: =P50*25.4 -> 7.3056193
...

Sheet Cover
J1: ='Calculation for sizing HDT '!D2 -> SALMAN PLATFORM
J2: Data Sheet For Air Dryer
A3: No | J3: Date | N3: ='Calculation for sizing HDT '!D3 -> 43869 | S3: Revision | W3: ='Calculation for sizing HDT '!D4 -> 0 | AB3: Page 1 of 2
A4: Data Sheet For Air Dryer
A26: =W3 -> 0 | D26: Issued For Information | P26: S.S.K. | U26: F.Kh | Z26: H.M | AE26: =N3 -> 43869
A27: Rev | D27: Status | P27: Prepared | U27: Checked | Z27: Approved | AE27: Date

Sheet Dryer Data Sheet
J1: =Cover!J1 -> SALMAN PLATFORM
J2: Data Sheet For Air Dryer
J3: Date | M3: =Cover!N3 -> 43869 | S3: Revision | W3: =Cover!W3 -> 0 | AB3: Page 2 of 2
A4: DRYER
A5: 1 | B5: Quantity | L5: 2 | S5: TYPE | Y5: ¢ | Z5: Heatless | AD5: £ | AE5: Heat Regenerated
A6: 2 | B6: Manufacturer | L6: HAVAYAR | S6: Area Classification | Y6: ¢ | Z6: Safe Area | AD6: £ | AE6: Hazardous Area
A7: 3 | B7: Model | L7: ='Calculation for sizing HDT '!G53 -> HDT-800 | S7: Change Over | Y7: £ | Z7: Manual | AD7: ¢ | AE7: Automatic
A8: 4 | B8: Cycle Time | L8: =IF('Calculation for sizing HDT '!D10='Calculation for sizing HDT '!G8,'Calculation for sizing HDT '!H8,IF('Calculation for sizing HDT '!D10='Calculation for sizing HDT '!G9,'Calculation for sizing HDT '!H9,IF('Calculation for sizing HDT '!D10='Calculation for sizing HDT '!G10,'Calculation for sizing HDT '!H10))) -> 10 min. | S8: Location | Y8: ¢ | Z8: Indoor | AD8: £ | AE8: Outdoor, Under shelter
A9: OPERATING CONDITIONS | S9: MECHANICAL DESIGN DATA
A10: 5 | B10: Gas To Be Dried | L10: AIR | S10: Design Code | AC10: ASME Sec VIII DIV I
A11: 6 | B11: Inlet Flow Rate, Nm3/hr | L11: ='Calculation for sizing HDT '!D8 -> 7000 | P11: (Note 1) | S11: Design Pressure, barg | AC11: =ROUNDDOWN($L$13+2,0) -> 18
A12: 7 | B12: Inlet Temperature, °C | L12: ='Calculation for sizing HDT '!D7 -> 20 | S12: Design Temperature, °C | AC12: 85
A13: 8 | B13: Max. Inlet Pressure, barg | L13: ='Calculation for sizing HDT '!D6 -> 16 | S13: Test pressure, barg | AC13: =1.3*AC11 -> 23.4
A14: 9 | B14: Rel. Humidity, % | L14: Saturated at inlet press. | S14: Corrosion Allowance, mm | AC14: ='Calculation for sizing HDT '!D9 -> 1.5
A15: 10 | B15: Dew Point, °C | L15: ='Calculation for sizing HDT '!D10 -> -20 | P15: °C | S15: Noise Limit, dBA | AC15: Max. 85
A16: 11 | B16: Allow. Press. Drop, bar | L16: 0.2 | S16: Dryer Type | AC16: Desiccant
A17: 12 | B17: Actual Press. Drop, bar | L17: 0.1 | S17: Drying Medium | AC17: Air
A18: 13 | B18: Outlet Flow Rate, Nm3/hr | L18: =$L$11*0.85 -> 5950 | S18: Regenerating Medium | AC18: Air
A19: 14 | B19: Duty | L19: Air
A20: CONSTRUCTION | S20: MATERIAL
A21: 15 | B21: Tower Qty. | L21: 2 | S21: Shell Material | AC21: =IF('Calculation for sizing HDT '!F93="-",'Calculation for sizing HDT '!G91,IF('Calculation for sizing HDT '!G93="-",'Calculation for sizing HDT '!F91)) -> SA516 Gr.70
A22: 16 | B22: Tower Design Code | L22: ASME Sec VIII DIV 1 | S22: Head Material | AC22: =IF(AC21="SA516 Gr.70","SA516 Gr.70",IF(AC21="SA-106 Gr. B","SA-234 WPB")) -> SA516 Gr.70
A23: 17 | B23: Safety valve Qty. | L23: 1 per Tower | S23: Interconnecting Piping Material | AC23: SA-106 Gr. B
A24: 18 | B24: Safety Valve Set Press, bar g | L24: =AC11 -> 18 | S24: Base Plate Material | AC24: C.S.
A25: 19 | B25: Manufacturer | L25: HAVAYAR | S25: Nozzle Flange / Neck | AC25: SA-105 / SA-106 Gr.B
A26: 20 | B26: Adsorbent Type | L26: Molecular Sieve | S26: Muffler | AC26: Aluminum
A27: 21 | S27: Internals | AC27: S.S.304
A28: THICKNESS | S28: NOZZLES
A29: 22 | B29: Shell Thickness(mm) | L29: =IF(AC21="SA-106 Gr. B",'Calculation for sizing HDT '!F93,IF(AC21="SA516 Gr.70",'Calculation for sizing HDT '!G93)) -> 10 | S29: Nozzles | W29: Size | Y29: Material | AE29: Type | AI29: Rating
A30: 23 | B30: =IF(AC22="SA516 Gr.70","Minimum Head Thickness After forming (mm)","Head Thickness (mm)") -> Minimum Head Thickness After forming (mm) | L30: =IF(AC21="SA516 Gr.70",'Vessel Weights'!$I$43,L29) -> 7.3056193 | S30: Inlet | W30: ='Calculation for sizing HDT '!L93 -> 6" | Y30: ='Calculation for sizing HDT '!M93 -> SA-106 Gr.B / SA-105 | AE30: ='Calculation for sizing HDT '!N93 -> S.O. / R.F. | AI30: ='Calculation for sizing HDT '!O93 -> 150#
A31: 24 | B31: Joint efficiency shell / head / Shell to Head | L31: 1.0 / 1.0 / 0.85 | S31: Outlet | W31: ='Calculation for sizing HDT '!L93 -> 6" | Y31: ='Calculation for sizing HDT '!M93 -> SA-106 Gr.B / SA-105 | AE31: ='Calculation for sizing HDT '!N93 -> S.O. / R.F. | AI31: ='Calculation for sizing HDT '!O93 -> 150#
A32: INSTRUMENTATION
A33: 25 | B33: Control Panel Type | I33: £ | J33: DDC15 | Q33: ¢ | R33: PLC | S33: Manual Override | AC33: £ | AD33: Yes | AI33: ¢ | AJ33: No
A34: 26 | B34: Press. Gauges | I34: ¢ | J34: Yes | Q34: £ | R34: No | S34: Control Voltage Transformer | AC34: £ | AD34: Yes | AI34: ¢ | AJ34: No
A35: 27 | B35: Temp. Gauges | I35: £ | J35: Yes | Q35: ¢ | R35: No | S35: Switch Failure Alarm | AC35: £ | AD35: Yes (LOCAL) | AI35: ¢ | AJ35: No
A36: 28 | B36: Safety Valve | I36: ¢ | J36: Yes | Q36: £ | R36: No | S36: High Humidity Alarm | AC36: ¢ | AD36: Yes | AI36: ¢ | AJ36: No
A37: 29 | B37: General Alarm | I37: ¢ | J37: Yes | Q37: £ | R37: No | S37: Pre-filter DPI | AC37: ¢ | AD37: Yes | AI37: £ | AJ37: No
A38: 30 | B38: Running Status | I38: ¢ | J38: Yes | Q38: £ | R38: No | S38: After-filter DPI | AC38: ¢ | AD38: Yes | AI38: £ | AJ38: No
A39: 31 | B39: Remote Start/Stop | I39: £ | J39: Yes | Q39: ¢ | R39: No | S39: Dew Point Indicator | AC39: ¢ | AD39: Yes (On PLC) | AI39: £ | AJ39: No
A40: 32 | S40: Dew Point Transmitter | AC40: ¢ | AD40: Yes | AI40: £ | AJ40: No
...

Sheet Evaluation Warning
A10: Created with a trial version of Syncfusion Essential XlsIO
