Workbook
Name Havayar.N2.Generator.Adsorbent.Weight: Table6[Adsorbent Weight, kg]
Name Havayar.N2.Generator.Dimensions: Table6[[#All],[Generator Dimensions]]
Name Havayar.N2.Generator.Models: Table6[N2 Model-Havayar]
Name Havayar.N2.Generator.Towers.Net.Volume: Table6[Towers Net Volume, Lit]
Name Havayar.N2.Generator.Volume: Table6[Adsorbent Volume, Lit]
Name Havayar.Receiver.Capacity: Table12[Actual Capacity]
Name Havayar.Receiver.Models: Table12[Model]
Name Oxymat.N2.Generator.Adsorbent.Weight: Table3[Adsorbent Weight, kg]
Name Oxymat.N2.Generator.Dimensions: Table3[Generator Dimensions]
Name Oxymat.N2.Generator.Models: Table3[N2 Model-Oxymat]
Name Oxymat.N2.Generator.Towers.Net.Volume: Table3[Towers Net Volume, Lit]
Name Oxymat.N2.Generator.Volume: Table3[Adsorbent Volume, Lit]

Sheet Equipment Selection
A1: Ctegory | B1: Data | C1: Unit | D1: Value | E1: Remarks
A2: General Data | B2: N2 Generator Inlet Pressure | C2: barg | D2: 7
B3: N2 Generator Bed Pressure Loss | C3: bar | D3: =IF(D8<=99.99,0.8,0.4) -> 0.8 | E3: Normally 0.8 barg for LP and 0.4 barg for HP
B4: N2 Generator Inlet Temperature | C4: °C | D4: 30 | E4: =IF(OR(AND(D4>50,D8<=99.99),AND(D4>40,D8>99.99)),"Inlet temperature is too high."," ")
B5: N2 Generator Product Range | D5: Oxymat
B6: Receiver Product Range | D6: Havayar
A7: N2 Generator Data | B7: Consumer's Required N2 Flow | C7: Nm3/hr | D7: 320
B8: Consumer's Required N2 Purity | C8: % | D8: 99.99 | E8: =IF(D8>99.99,"High Purity Configuration is required.","Low Purity Configuration is required.") -> Low Purity Configuration is required.
B9: N2 Generators on Duty | C9: - | D9: 1 | E9: =IF(AND(D28="Custom model Required",D8>99.99),"Increase the number of N2 Generators on duty."," ")
B10: CMS Manufacturer | C10: - | D10: SHE | E10: =IF(AND(D10="SHE",D8>99.99),"For High Purity solely select Kurary."," ")
B11: N2 Generator Air Consumption Method | D11: Max 0% more than required | E11: Max 0% more than required | F11: Max 0% more than required
B12: N2 Delivery Pressure | C12: barg | D12: =D2-D3-IF(D8>99.99,1.1) -> 6.2
A13: N2 Generator | B13: CMS Nominal Capacity | C13: Nm3/m3h | D13: =IF(D10="Kurary",10^(0.000491*LOG10(100-D8)^6+0.003001*LOG10(100-D8)^5+0.008966*LOG10(100-D8)^4+0.037449*LOG10(100-D8)^3+0.093963*LOG10(100-D8)^2+0.263951*LOG10(100-D8)+2.285782),"N/A") -> N/A | E13: @20°C, 6.4barg for Kurary
C14: Nm3/ton.h | D14: =IF(D10="Kurary","N/A",IF(D8<=99,10^(0.806039*LOG10(100-D8)^3-1.113474*LOG10(100-D8)^2+0.754*LOG10(100-D8)+2.50515),10^(0.010816*LOG10(100-D8) ^3+ 0.02797*LOG10(100-D8) ^2+ 0.200085 *LOG10(100-D8)+ 2.50515))) -> 134.99945 | E14: @30°C, 8barg for SHE
B15: Nominal Air/N2 | C15: - | D15: =IF(D10="kurary",0.0094403599*LOG10(100-D8) ^6+ 0.0499013483*LOG10(100-D8) ^5+ 0.0421019779*LOG10(100-D8) ^4- 0.1439716442*LOG10(100-D8) ^3- 0.1176149993*LOG10(100-D8) ^2- 0.7031367786 *LOG10(100-D8)+ 2.4268779343,IF(D8<=98,10^(-0.193369*LOG10(100-D8) ^2+ 0.040839 *LOG10(100-D8)+ 0.366957),10^(-0.029299*LOG10(100-D8) ^3- 0.094031*LOG10(100-D8) ^2- 0.170283 *LOG10(100-D8)+ 0.424576))) -> 4.2015545
B16: Adsorption Temperature | C16: °C | D16: =D4 -> 30
B17: Capacity Temperature Correction | D17: =MIN(IF(D10="Kurary",IF(D8<=99.95,IF(D16<=35,1-(1-0.994)*(D16-20),0.91-(1-0.98)*(D16-35)),IF(D16<=35,1-(1-0.99)*(D16-20),0.85-(1-0.98)*(D16-35))),IF(D16<=40,1-0.015*(D16-30),0.85-0.03*(D16-40))),1) -> 1
B18: Air/N2 Temperature Correction | D18: =IF(D10="Kurary",IF(D16<=20,1,IF(D8<=99.95,IF(D16<=35,1+(1.007-1)*(D16-20),1.105+(1.01-1)*(D16-35)),IF(D16<=35,1+(1.0142-1)*(D16-20),1.213+(1.015-1)*(D16-35)))),IF(D10="SHE",IF(D16<=30,1,0.000000058775058*D16 ^5- 0.000014590199083*D16 ^4+ 0.001407216486304*D16 ^3- 0.065564545981107*D16 ^2+ 1.4868407102015 *D16- 12.2017845116702))) -> 1
B19: Adsorption Pressure | C19: barg | D19: =D2-0.5*D3 -> 6.6
B20: Capacity Pressure Correction | D20: =IF(D10="Kurary",-0.0001846104*D19 ^6+ 0.0067119732*D19 ^5- 0.099103766*D19 ^4+ 0.756628608*D19 ^3- 3.1462859806*D19 ^2+ 6.9343368208*D19- 5.9697020246,- 0.018839*D19 ^3+ 0.415*D19 ^2- 2.881161 *D19+ 7.135) -> 0.78060026
B21: Air/N2 Pressure Correction | D21: =IF(D10="Kurary",IF(D19<=6.4, 0.0005103731*D19 ^4- 0.0129155014*D19 ^3+ 0.130994319*D19 ^2- 0.639306242 *D19+ 2.2547418268,IF(D8<=99.9,1,1+(-1-LOG10(100-D8))*(-0.005948*(D19-6.4)^3+0.029567*(D19-6.4)^2-0.008657*(D19-6.4)))),IF(D8<=99.9,-0.0030682643427724*D19 ^3+ 0.0755446623093405*D19 ^2- 0.633151779230019 *D19+ 2.80130718954188,0.017857142857146*D19 ^3- 0.382142857142938*D19 ^2+ 2.64761904761971 *D19- 4.86666666666849)) -> 1.0953333
B22: Capacity Correction Factor after 5 years | D22: 0.9
B23: Cycle time Capacity Correction Factor | D23: =IF(D8<=99.99,1,0.545) -> 1
B24: Actual Capacity | C24: =IF(D10="Kurary",C13,C14) -> Nm3/ton.h | D24: =IF(D10="Kurary",D13,D14)*D17*D20*D22*D23 -> 94.842545
B25: Required Air/N2 | C25: - | D25: =D15*D18*D21 -> 4.6021027
B26: Required CMS per Generator | C26: lit | D26: =IF(D10="Kurary",D7/D9/(D24)*1000,D27/0.65) -> 5190.7896
C27: kg | D27: =IF(D10="Kurary",D26*0.65,D7/D9/D24*1000) -> 3374.0132
B28: N2 Generator Model | C28: Required | D28: =_xlfn.IFNA(IF(D26=0,"#N/A",IF(D10="Kurary",INDEX(INDIRECT(CONCATENATE(D5,".N2.Generator.Models")),MATCH('Equipment Selection'!D26,INDIRECT(CONCATENATE(D5,".N2.Generator.Volume")),-1),1),INDEX(INDIRECT(CONCATENATE(D5,".N2.Generator.Models")),MATCH('Equipment Selection'!D27,INDIRECT(CONCATENATE(D5,".N2.Generator.Adsorbent.Weight")),-1),1))),"Custom Model Required") -> N-4500x2
C29: Selected | D29: N-4500x2
B30: Capacity Ratio: 1 Size Less Than Required Model / Required Capacity | C30: % | D30: =INDEX(INDIRECT(CONCATENATE(D5,".N2.Generator.Adsorbent.Weight")),MATCH('Equipment Selection'!D28,INDIRECT(CONCATENATE(D5,".N2.Generator.Models")),0)+1)/D27*100 -> 69.617647
B31: Capacity Ratio: Selected Model / Required Capacity | C31: % | D31: =INDEX(INDIRECT(CONCATENATE(D5,".N2.Generator.Adsorbent.Weight")),MATCH('Equipment Selection'!D29,INDIRECT(CONCATENATE(D5,".N2.Generator.Models")),0))/D27*100 -> 103.65162
B32: Consumption Method | D32: =IFERROR(MID(D11,FIND("%",D11)-2,2),"Full") -> 0
B33: Total CMS in Operation (According to the Consumption Method) | C33: =IF(D28="Custom Model Required","kg",IF(D10="Kurary","lit","kg")) -> kg | D33: =IF(D28="Custom Model Required",D27*D9,IF(D10="Kurary",MIN(INDEX(INDIRECT(CONCATENATE(D5,".N2.Generator.Volume")),MATCH('Equipment Selection'!D29,INDIRECT(CONCATENATE(D5,".N2.Generator.Models")),0)),IF(D32="Full",99999999999,(1+D32/100)*D26)),MIN(INDEX(INDIRECT(CONCATENATE(D5,".N2.Generator.Adsorbent.Weight")),MATCH('Equipment Selection'!D29,INDIRECT(CONCATENATE(D5,".N2.Generator.Models")),0)),IF(D32="Full",99999999999,(1+D32/100)*'Equipment Selection'!D27)))*D9) -> 3374.0132
B34: Required CMS Filling per Generator | C34: kg | D34: =IF(D28="Custom Model Required",D27*0.68/0.65,MIN(INDEX(INDIRECT(CONCATENATE(D5,".N2.Generator.Towers.Net.volume")),MATCH('Equipment Selection'!D29,INDIRECT(CONCATENATE(D5,".N2.Generator.Models")),0)),99999999999)*0.68) -> 3851.1891
B35: Tower Net Volume (One tower) | C35: lit | D35: =IF(D28="Custom Model Required",D26*1.2,MIN(INDEX(INDIRECT(CONCATENATE(D5,".N2.Generator.Towers.Net.volume")),MATCH('Equipment Selection'!D29,INDIRECT(CONCATENATE(D5,".N2.Generator.Models")),0)),99999999999)/RIGHT(D29,1))/2 -> 1415.8783
B36: Total Available N2 Flow | C36: Nm3/hr | D36: =IF(AND(D28="Custom Model Required",D10="Kurary"),D33/0.65/1000*D24,D33/1000*D24) -> 320
B37: N2 Generators Dry Air Consumption | C37: Nm3/hr | D37: =D36*D25+D9*IF(D8<=99.99,((0.9*(D19-2.5)*RIGHT(D29,1)*(D35/1000)*273.15)/(273.15+D16))*(1800/55),D19*D35/1000*273.15*RIGHT(D29,1)/(273.15+D16)*(1800/110)) -> 1780.8041
A38: Dry Air Receiver | B38: Required Dry Air Receiver Size | C38: lit | D38: =IF(D8>99.99,2*D35,0.15*D37/D9/90/0.5*1000/RIGHT(D29,1)) -> 2968.0068
B39: Required Dry Air Receiver Model for Each N2 Generator | C39: =D6 -> Havayar | D39: =INDEX(INDIRECT(CONCATENATE(D6,".Receiver.Models")),MATCH('Equipment Selection'!D38,INDIRECT(CONCATENATE(D6,".Receiver.Capacity")),-1)) -> AR-3500
A40: N2 Receiver | B40: Required N2 Receiver Size | C40: lit | D40: =IF(D8>99.99,2.8*D35,(D36/D9/180/0.5*1000+0.15*D33*D22/D9*D12/0.5)/RIGHT(D29,1)) -> 4601.8268
...

Sheet Datasheet
G1: ='[1]Page1-2'!G1:O3 -> Title: Data Sheet for HN-700 PSA Nitrogen Generator | P1: ='[1]Page1-2'!P1:U1 -> Document Number: HY-ME-DS-N2-0014
P2: ='[1]Page1-2'!P2:U2 -> Rev: 00
P3: Page : 2 of 2
A4: 1 | B4: Operation
A5: =A4+1 -> 2 | B5: Model | D5: ='Equipment Selection'!D29 -> N-4500x2 | G5: Service: | I5: Nitrogen Packages | M5: N2 Generator Type: | P5: Pressure Swing Adsorption (PSA)
A6: =A5+1 -> 3 | B6: Qty. (Op.) | D6: ='Equipment Selection'!D9 -> 1 | G6: Inlet Fluid: | I6: Compressed Dry Air | M6: Manufacturer: | P6: Havayar Industrial Group
A7: =A6+1 -> 4 | B7: Nitrogen Purity | G7: =CONCATENATE('Equipment Selection'!D8,"%") -> 99.99%
A8: =A7+1 -> 5 | B8: Nitrogen Impurity | G8: =IF('Equipment Selection'!D8<=99.9,CONCATENATE(100-'Equipment Selection'!D8,"%"),CONCATENATE(1000000-10000*'Equipment Selection'!D8,"ppm")) -> 100ppm
A9: =A8+1 -> 6 | B9: Production Rate(Sm3/hr1,2) | G9: =CONCATENATE(D6,"x",ROUNDUP('Equipment Selection'!D36/Datasheet!D6/0.92,2)) -> 1x347.83
A10: =A9+1 -> 7 | B10: Air Feed (Nm3/min) | G10: =CONCATENATE(D6,"x",ROUNDUP('Equipment Selection'!D37/Datasheet!D6/60,2)) -> 1x29.69
A11: =A10+1 -> 8 | B11: Min. N2 Receiver (Liters) | G11: =ROUNDUP('Equipment Selection'!D40,-2) -> 4700
A12: =A11+1 -> 9 | B12: Min. Air Receiver (Liters) | G12: =ROUNDUP('Equipment Selection'!D38,-2) -> 3000
A13: =A12+1 -> 10 | B13: Empty Weight (kg) | E13: 2000 | H13: CMS Fill Weight (kg) | L13: ='Equipment Selection'!D34 -> 3851.1891
A14: =A13+1 -> 11 | B14: Inlet Press. (barg) | F14: ='Equipment Selection'!D2 -> 7 | G14: Outlet Press. (barg) | J14: ='Equipment Selection'!D12 -> 6.2 | L14: Inlet Dew Point (°C) | O14: =CONCATENATE(IF('Equipment Selection'!D8>99.99,"-20","+3")," or less") -> +3 or less | Q14: Inlet Temperature (°C) | U14: ='Equipment Selection'!D4 -> 30
A15: =A14+1 -> 12 | B15: Dimensions LxWxH (cm) | F15: =INDEX(INDIRECT(CONCATENATE('Equipment Selection'!D5,".N2.Generator.Dimensions")),MATCH('Equipment Selection'!D29,INDIRECT(CONCATENATE('Equipment Selection'!D5,".N2.Generator.Models")),0)) -> 200x250x300 | H15: Shipping Dimensions LxWxH (cm) | M15: =CONCATENATE(LEFT(F15,SEARCH("x",F15)-1)+20,"x",MID(F15,SEARCH("x",F15)+1,SEARCH("x",F15,5)-SEARCH("x",F15)-1)+20,"x",RIGHT(F15,3)+25) -> 220x270x325 | O15: Maintenance Area LxWxH (cm) | T15: =CONCATENATE(LEFT(F15,SEARCH("x",F15)-1)+20,"x",MID(F15,SEARCH("x",F15)+1,SEARCH("x",F15,5)-SEARCH("x",F15)-1)+70,"x",RIGHT(F15,3)+20) -> 220x320x320
A16: =A15+1 -> 13 | B16: Mechanical Design Data | K16: Connections
A17: =A16+1 -> 14 | B17: Construction Code | H17: Manufacturer STD. | K17: Conn. | M17: Size (in.) | O17: Rating | P17: Facing | R17: Remarks
A18: =A17+1 -> 15 | B18: Design / Hydro Test pressure (barg) | H18: 10 / 13 | K18: Inlet | M18: 1 1/2" | O18: 3000# | P18: Threaded | R18: -
A19: =A18+1 -> 16 | B19: Design Temperature (°C) | H19: 85 | K19: Outlet | M19: 1 1/2" | O19: 3000# | P19: Threaded | R19: 1" for High Purity models
A20: =A19+1 -> 17 | B20: Corrosion Allowance, mm | H20: 0.5 | K20: PSV | M20: 1/2" | O20: 3000# | P20: Threaded | R20: 1 per tower, set 10.5 barg
A21: =A20+1 -> 18 | B21: Tower Dimensions O.D.xW.L-W.L. (mm) | H21: 863x1500 | K21: Hand Hole | M21: 8" | O21: Manufacturer STD. | R21: with Blind
A22: =A21+1 -> 19 | B22: Head Type, Straight Flange (mm) | H22: 2.11:1 Elliptical, 50 | K22: Instrumentations
A23: =A22+1 -> 20 | B23: Shell / Head A.F. Thickness (mm) / J.E. | H23: 6 / 6 / 0.7 | K23: Control Panel Loaction | O23: On Skid
A24: =A23+1 -> 21 | B24: Insulation | H24: N.A. | K24: Control Panel Type / Model | O24: PLC Type / siemens S7-1200
A25: =A24+1 -> 22 | B25: Paint Material / Thickness (µ) / RAL | H25: Epoxy / 120 / 7015 | K25: Press. Gauge / Transmitter | O25: Yes / Yes
A26: =A25+1 -> 23 | B26: Materials | K26: Oxygen Analyzer | O26: Yes (0-25%)
A27: =A26+1 -> 24 | B27: Shell / Head | F27: A 283-C / A 283-C | K27: Oxygen Monitor | O27: 0-25%, Includes alarm function (through control)
A28: =A27+1 -> 25 | B28: Nozzle Neck | F28: A 106-B | K28: HMI | O28: Touch screen 7"
A29: =A28+1 -> 26 | B29: Interconnecting Piping | F29: Copper | K29: Signals | O29: Remote Alarm / Running Status
A30: =A29+1 -> 27 | B30: Flanges | F30: A 105 | K30: Electricity-Power (W) | O30: 100
A31: =A30+1 -> 28 | B31: Internal Diffuser | F31: Brass | K31: Purity Control (Optional) | O31: If the product purity falls below the required value, it automatically purges the product into the atmosphere until the desired purity is reached.
A32: =A31+1 -> 29 | B32: Supports, Baseplate, Struc. | F32: Carbon Steel
A33: =A32+1 -> 30 | B33: Inspection & Testing | K33: Sketch
A34: =A33+1 -> 31 | B34: Visual Testing | F34: Yes
A35: =A34+1 -> 32 | B35: Penetration Testing | F35: 10% on W.L. / 100% on T-Joint
A36: =A35+1 -> 33 | B36: Radiography Testing | F36: 100% on T-Joint
A37: =A36+1 -> 34 | B37: Ultrasonic Testing | F37: No
A38: =A37+1 -> 35 | B38: Noise Test | F38: Yes, max 85 dBA
A39: =A38+1 -> 36 | B39: Functional Testing | F39: Yes
A40: =A39+1 -> 37 | B40: Site Conditions
...

Sheet Evaluation Warning
A10: Created with a trial version of Syncfusion Essential XlsIO
